Workbook

Sheet Summary
B1: How to run
B3: PVXS_LOG="pvxs.perf=INFO" ./bin/darwin-aarch64/pvxperf \
C4: --setup-cms \
C5: --keychain test/O.darwin-aarch64/server1.p12 \
C6: --duration 5 \
C7: --output /tmp/pvxperf-full-results.csv 2>&1
B8: cat /tmp/pvxperf-full-results.csv
B10: * paste csv contents in last tab to see graphs
B12: Summary
B14: Environment | H14: Benchmark Config | M14: Transport
C15: Platform | D15: macOS darwin-aarch64 (Apple Silicon) | I15: 1000 parallel subscriptions | N15: loopback (127.0.0.1)
C16: EPICS Base | D16: R7.0.10 | I16: 5s measurement per data point | N16: isolated server ↔ client in same process
C17: PVXS | D17: 1.5.0 | I17: 100 warm-up updates
C18: OpenSSL | D18: 3.6.1
B20: Results
B21: Sequential Mode (1 subscription)
B22: Payload | C22: CA | D22: PVA | E22: SPVA | F22: SPVA_CERTMON
B23: 1B | C23: =seq!$C2 -> 37368.62 | D23: =seq!$C8 -> 107248.4 | E23: =seq!$C14 -> 75098.86 | F23: =seq!$C20 -> 73196.68
B24: 10B | C24: =seq!$C3 -> 33625.18 | D24: =seq!$C9 -> 107652.8 | E24: =seq!$C15 -> 75308.74 | F24: =seq!$C21 -> 75403.38
B25: 100B | C25: =seq!$C4 -> 32086.1 | D25: =seq!$C10 -> 99042.12 | E25: =seq!$C16 -> 74584.54 | F25: =seq!$C22 -> 73217.38
B26: 1KB | C26: =seq!$C5 -> 52793.06 | D26: =seq!$C11 -> 84055.34 | E26: =seq!$C17 -> 57063.42 | F26: =seq!$C23 -> 59068.8
B27: 10KB | C27: =seq!$C6 -> 34337.46 | D27: =seq!$C12 -> 54317.18 | E27: =seq!$C18 -> 26414.36 | F27: =seq!$C24 -> 26397.26
B28: 100KB | C28: =seq!$C7 -> 24491.16 | D28: =seq!$C13 -> 14339.56 | E28: =seq!$C19 -> 4232.674 | F28: =seq!$C25 -> 4197.098
B30: Parallel Mode (1000 subscriptions)
B31: Payload | C31: CA | D31: PVA | E31: SPVA | F31: SPVA_CERTMON
B32: 1B | C32: =par!$C2 -> 58071.08 | D32: =par!$C8 -> 257999.4 | E32: =par!$C14 -> 70914.88 | F32: =par!$C20 -> 70928.9
B33: 10B | C33: =par!$C3 -> 57867.3 | D33: =par!$C9 -> 161745.2 | E33: =par!$C15 -> 43413.58 | F33: =par!$C21 -> 43837.46
B34: 100B | C34: =par!$C4 -> 56693.66 | D34: =par!$C10 -> 160598 | E34: =par!$C16 -> 52606.18 | F34: =par!$C22 -> 54729.88
B35: 1KB | C35: =par!$C5 -> 55102.6 | D35: =par!$C11 -> 67008.36 | E35: =par!$C17 -> 52841.74 | F35: =par!$C23 -> 54275
B36: 10KB | C36: =par!$C6 -> 26119.06 | D36: =par!$C12 -> 54524.1 | E36: =par!$C18 -> 24178.76 | F36: =par!$C24 -> 23893.42
B37: 100KB | C37: =par!$C7 -> 11354.42 | D37: =par!$C13 -> 13769.44 | E37: =par!$C19 -> 3732.224 | F37: =par!$C25 -> 3792.05
B39: All values are updates/second (application-layer throughput).
B40: Drops are expected — they reflect squashed updates under load, not errors.
B42: Key Observations
B43: PVA vs SPVA vs SPVA_CERTMON
C44: Virtually identical throughput
C45: TLS encryption and certificate monitoring add no measurable overhead.
B47: PVA/SPVA
C48: parallel scales ~4-7x over sequential for small payloads (1B–100B)
C49: tapering at larger sizes.
...

Sheet charts
C40: PVA performance is very sensitive to changes in pipeline window when it has larger payloads. In the above benchmark | M40: This graph compares the increase in aggregated data throughput that can be achieved by applying a thousand subscribers
C41: CA has an effective window of 144 while PVA, and SPVA have a window of 4 for payloads of 100KB. This is why we see | M41: to the same source with varying payload sizes
C42: different performance numbers for CA vs PVA - apples to oranges!
C44: What these sets of graphs DO show conclusively is that PVA compared performs nearly 290% netter than CA. | M44: PVA and SPVA again perform exactly the same and both outperform CA by roughly 4 times
C45: SPVA (with or without certificate monitoring) performs 200% better than CA with about 30% lower throughput than PVA

Sheet 3d charts

Sheet Connection Phase Timing
B44: =csv_phase!$U1 -> Phase | C44: PVA | F44: SPVA | H44: ± % | J44: SPVA Cert Monitor | L44: ± %
B45: Search | C45: =csv_phase!$V2 -> 2.9872 | D45: =_xlfn.CONCAT("± ", ROUND(csv_phase!$W2,2), " ms") -> ± 2.51 ms | F45: =csv_phase!$X2 -> 1.97126 | G45: =_xlfn.CONCAT("± ", ROUND(csv_phase!$W2,1), " ms") -> ± 2.5 ms | H45: =((F45-C45)/C45)*100 -> -34.009775 | J45: =csv_phase!$Z2 -> 4.28358 | K45: =_xlfn.CONCAT("± ", ROUND(csv_phase!$AA2,2), " ms") -> ± 2.75 ms | L45: =((J45-C45)/C45)*100 -> 43.397831
B46: Connect | C46: =csv_phase!$V3 -> 0.12036 | D46: =_xlfn.CONCAT("± ", ROUND(csv_phase!$W3,2), " ms") -> ± 0.12 ms | F46: =csv_phase!$X3 -> 5.22268 | G46: =_xlfn.CONCAT("± ", ROUND(csv_phase!$W3,1), " ms") -> ± 0.1 ms | H46: =((F46-C46)/C46)*100 -> 4239.2157 | J46: =csv_phase!$Z3 -> 13.75054 | K46: =_xlfn.CONCAT("± ", ROUND(csv_phase!$AA3,2), " ms") -> ± 3.32 ms | L46: =((J46-C46)/C46)*100 -> 11324.51
B47: Validate | C47: =csv_phase!$V4 -> 0.29078 | D47: =_xlfn.CONCAT("± ", ROUND(csv_phase!$W4,2), " ms") -> ± 0.2 ms | F47: =csv_phase!$X4 -> 0.53796 | G47: =_xlfn.CONCAT("± ", ROUND(csv_phase!$W4,1), " ms") -> ± 0.2 ms | H47: =((F47-C47)/C47)*100 -> 85.005846 | J47: =csv_phase!$Z4 -> 0.74076 | K47: =_xlfn.CONCAT("± ", ROUND(csv_phase!$AA4,2), " ms") -> ± 0.29 ms | L47: =((J47-C47)/C47)*100 -> 154.74929
B48: Create Channel | C48: =csv_phase!$V5 -> 0.4616 | D48: =_xlfn.CONCAT("± ", ROUND(csv_phase!$W5,2), " ms") -> ± 0.38 ms | F48: =csv_phase!$X5 -> 0.34066 | G48: =_xlfn.CONCAT("± ", ROUND(csv_phase!$W5,1), " ms") -> ± 0.4 ms | H48: =((F48-C48)/C48)*100 -> -26.200173 | J48: =csv_phase!$Z5 -> 15.26008 | K48: =_xlfn.CONCAT("± ", ROUND(csv_phase!$AA5,2), " ms") -> ± 2.45 ms | L48: =((J48-C48)/C48)*100 -> 3205.9099
B49: =csv_phase!$U6 -> TOTAL | C49: =csv_phase!$V6 -> 3.85994 | D49: =_xlfn.CONCAT("± ", ROUND(SUM(csv_phase!$W2:$W5),2), " ms") -> ± 3.2 ms | F49: =csv_phase!$X6 -> 8.07256 | G49: =_xlfn.CONCAT("± ", ROUND(SUM(csv_phase!$W2:$W5),1), " ms") -> ± 3.2 ms | H49: =((F49-C49)/C49)*100 -> 109.13693 | J49: =csv_phase!$Z6 -> 34.03496 | K49: =_xlfn.CONCAT("± ", ROUND(SUM(csv_phase!$W2:$AA5),2), " ms") -> ± 59.18 ms | L49: =((J49-C49)/C49)*100 -> 781.74842

Sheet seq
A1: protocol | B1: payload_bytes | C1: updates_per_second | D1: stdandard_dev | E1: row to choose
A2: {=INDIRECT(CONCATENATE("csv!A",$E2))} -> CA | B2: {=INDIRECT(CONCATENATE("csv!D",$E2))} -> 1 | C2: =AVERAGE(INDIRECT(CONCATENATE("csv!G",$E2)):INDIRECT(CONCATENATE("csv!G",($E2)+4))) -> 37368.62 | D2: =_xlfn.STDEV.S(INDIRECT(CONCATENATE("csv!G",$E2)):INDIRECT(CONCATENATE("csv!G",($E2)+4))) -> 5258.4625 | E2: =2 -> 2
A3: {=INDIRECT(CONCATENATE("csv!A",$E3))} -> CA | B3: {=INDIRECT(CONCATENATE("csv!D",$E3))} -> 10 | C3: =AVERAGE(INDIRECT(CONCATENATE("csv!G",$E3)):INDIRECT(CONCATENATE("csv!G",($E3)+4))) -> 33625.18 | D3: =_xlfn.STDEV.S(INDIRECT(CONCATENATE("csv!G",$E3)):INDIRECT(CONCATENATE("csv!G",($E3)+4))) -> 3400.8573 | E3: =E2+25 -> 27
A4: {=INDIRECT(CONCATENATE("csv!A",$E4))} -> CA | B4: {=INDIRECT(CONCATENATE("csv!D",$E4))} -> 100 | C4: =AVERAGE(INDIRECT(CONCATENATE("csv!G",$E4)):INDIRECT(CONCATENATE("csv!G",($E4)+4))) -> 32086.1 | D4: =_xlfn.STDEV.S(INDIRECT(CONCATENATE("csv!G",$E4)):INDIRECT(CONCATENATE("csv!G",($E4)+4))) -> 3737.5153 | E4: =E3+25 -> 52
A5: {=INDIRECT(CONCATENATE("csv!A",$E5))} -> CA | B5: {=INDIRECT(CONCATENATE("csv!D",$E5))} -> 1000 | C5: =AVERAGE(INDIRECT(CONCATENATE("csv!G",$E5)):INDIRECT(CONCATENATE("csv!G",($E5)+4))) -> 52793.06 | D5: =_xlfn.STDEV.S(INDIRECT(CONCATENATE("csv!G",$E5)):INDIRECT(CONCATENATE("csv!G",($E5)+4))) -> 5938.618 | E5: =E4+25 -> 77
A6: {=INDIRECT(CONCATENATE("csv!A",$E6))} -> CA | B6: {=INDIRECT(CONCATENATE("csv!D",$E6))} -> 10000 | C6: =AVERAGE(INDIRECT(CONCATENATE("csv!G",$E6)):INDIRECT(CONCATENATE("csv!G",($E6)+4))) -> 34337.46 | D6: =_xlfn.STDEV.S(INDIRECT(CONCATENATE("csv!G",$E6)):INDIRECT(CONCATENATE("csv!G",($E6)+4))) -> 971.7922 | E6: =E5+25 -> 102
A7: {=INDIRECT(CONCATENATE("csv!A",$E7))} -> CA | B7: {=INDIRECT(CONCATENATE("csv!D",$E7))} -> 100000 | C7: =AVERAGE(INDIRECT(CONCATENATE("csv!G",$E7)):INDIRECT(CONCATENATE("csv!G",($E7)+4))) -> 24491.16 | D7: =_xlfn.STDEV.S(INDIRECT(CONCATENATE("csv!G",$E7)):INDIRECT(CONCATENATE("csv!G",($E7)+4))) -> 434.26837 | E7: =E6+25 -> 127
A8: {=INDIRECT(CONCATENATE("csv!A",$E8))} -> PVA | B8: {=INDIRECT(CONCATENATE("csv!D",$E8))} -> 1 | C8: =AVERAGE(INDIRECT(CONCATENATE("csv!G",$E8)):INDIRECT(CONCATENATE("csv!G",($E8)+4))) -> 107248.4 | D8: =_xlfn.STDEV.S(INDIRECT(CONCATENATE("csv!G",$E8)):INDIRECT(CONCATENATE("csv!G",($E8)+4))) -> 3345.5659 | E8: =E7+25 -> 152
A9: {=INDIRECT(CONCATENATE("csv!A",$E9))} -> PVA | B9: {=INDIRECT(CONCATENATE("csv!D",$E9))} -> 10 | C9: =AVERAGE(INDIRECT(CONCATENATE("csv!G",$E9)):INDIRECT(CONCATENATE("csv!G",($E9)+4))) -> 107652.8 | D9: =_xlfn.STDEV.S(INDIRECT(CONCATENATE("csv!G",$E9)):INDIRECT(CONCATENATE("csv!G",($E9)+4))) -> 5306.347 | E9: =E8+25 -> 177
A10: {=INDIRECT(CONCATENATE("csv!A",$E10))} -> PVA | B10: {=INDIRECT(CONCATENATE("csv!D",$E10))} -> 100 | C10: =AVERAGE(INDIRECT(CONCATENATE("csv!G",$E10)):INDIRECT(CONCATENATE("csv!G",($E10)+4))) -> 99042.12 | D10: =_xlfn.STDEV.S(INDIRECT(CONCATENATE("csv!G",$E10)):INDIRECT(CONCATENATE("csv!G",($E10)+4))) -> 9703.4569 | E10: =E9+25 -> 202
A11: {=INDIRECT(CONCATENATE("csv!A",$E11))} -> PVA | B11: {=INDIRECT(CONCATENATE("csv!D",$E11))} -> 1000 | C11: =AVERAGE(INDIRECT(CONCATENATE("csv!G",$E11)):INDIRECT(CONCATENATE("csv!G",($E11)+4))) -> 84055.34 | D11: =_xlfn.STDEV.S(INDIRECT(CONCATENATE("csv!G",$E11)):INDIRECT(CONCATENATE("csv!G",($E11)+4))) -> 5188.5478 | E11: =E10+25 -> 227
A12: {=INDIRECT(CONCATENATE("csv!A",$E12))} -> PVA | B12: {=INDIRECT(CONCATENATE("csv!D",$E12))} -> 10000 | C12: =AVERAGE(INDIRECT(CONCATENATE("csv!G",$E12)):INDIRECT(CONCATENATE("csv!G",($E12)+4))) -> 54317.18 | D12: =_xlfn.STDEV.S(INDIRECT(CONCATENATE("csv!G",$E12)):INDIRECT(CONCATENATE("csv!G",($E12)+4))) -> 2759.5275 | E12: =E11+25 -> 252
A13: {=INDIRECT(CONCATENATE("csv!A",$E13))} -> PVA | B13: {=INDIRECT(CONCATENATE("csv!D",$E13))} -> 100000 | C13: =AVERAGE(INDIRECT(CONCATENATE("csv!G",$E13)):INDIRECT(CONCATENATE("csv!G",($E13)+4))) -> 14339.56 | D13: =_xlfn.STDEV.S(INDIRECT(CONCATENATE("csv!G",$E13)):INDIRECT(CONCATENATE("csv!G",($E13)+4))) -> 508.47439 | E13: =E12+25 -> 277
A14: {=INDIRECT(CONCATENATE("csv!A",$E14))} -> SPVA | B14: {=INDIRECT(CONCATENATE("csv!D",$E14))} -> 1 | C14: =AVERAGE(INDIRECT(CONCATENATE("csv!G",$E14)):INDIRECT(CONCATENATE("csv!G",($E14)+4))) -> 75098.86 | D14: =_xlfn.STDEV.S(INDIRECT(CONCATENATE("csv!G",$E14)):INDIRECT(CONCATENATE("csv!G",($E14)+4))) -> 640.74064 | E14: =E13+25 -> 302
... A25: {=INDIRECT(CONCATENATE("csv!A",$E25))} -> SPVA_CERTMON | B25: {=INDIRECT(CONCATENATE("csv!D",$E25))} -> 100000 | C25: =AVERAGE(INDIRECT(CONCATENATE("csv!G",$E25)):INDIRECT(CONCATENATE("csv!G",($E25)+4))) -> 4197.098 | D25: =_xlfn.STDEV.S(INDIRECT(CONCATENATE("csv!G",$E25)):INDIRECT(CONCATENATE("csv!G",($E25)+4))) -> 189.27337 | E25: =E24+25 -> 577

Sheet par
A1: protocol | B1: payload_bytes | C1: updates_per_second | D1: standard_dev | E1: row to choose
A2: {=INDIRECT(CONCATENATE("csv!A",$E2))} -> CA | B2: {=INDIRECT(CONCATENATE("csv!D",$E2))} -> 1 | C2: =AVERAGE(INDIRECT(CONCATENATE("csv!G",$E2)):INDIRECT(CONCATENATE("csv!G",($E2)+4))) -> 58071.08 | D2: =_xlfn.STDEV.S(INDIRECT(CONCATENATE("csv!G",$E2)):INDIRECT(CONCATENATE("csv!G",($E2)+4))) -> 2306.3854 | E2: 22
A3: {=INDIRECT(CONCATENATE("csv!A",$E3))} -> CA | B3: {=INDIRECT(CONCATENATE("csv!D",$E3))} -> 10 | C3: =AVERAGE(INDIRECT(CONCATENATE("csv!G",$E3)):INDIRECT(CONCATENATE("csv!G",($E3)+4))) -> 57867.3 | D3: =_xlfn.STDEV.S(INDIRECT(CONCATENATE("csv!G",$E3)):INDIRECT(CONCATENATE("csv!G",($E3)+4))) -> 2399.5449 | E3: =E2+25 -> 47
A4: {=INDIRECT(CONCATENATE("csv!A",$E4))} -> CA | B4: {=INDIRECT(CONCATENATE("csv!D",$E4))} -> 100 | C4: =AVERAGE(INDIRECT(CONCATENATE("csv!G",$E4)):INDIRECT(CONCATENATE("csv!G",($E4)+4))) -> 56693.66 | D4: =_xlfn.STDEV.S(INDIRECT(CONCATENATE("csv!G",$E4)):INDIRECT(CONCATENATE("csv!G",($E4)+4))) -> 2893.3484 | E4: =E3+25 -> 72
A5: {=INDIRECT(CONCATENATE("csv!A",$E5))} -> CA | B5: {=INDIRECT(CONCATENATE("csv!D",$E5))} -> 1000 | C5: =AVERAGE(INDIRECT(CONCATENATE("csv!G",$E5)):INDIRECT(CONCATENATE("csv!G",($E5)+4))) -> 55102.6 | D5: =_xlfn.STDEV.S(INDIRECT(CONCATENATE("csv!G",$E5)):INDIRECT(CONCATENATE("csv!G",($E5)+4))) -> 1757.8141 | E5: =E4+25 -> 97
A6: {=INDIRECT(CONCATENATE("csv!A",$E6))} -> CA | B6: {=INDIRECT(CONCATENATE("csv!D",$E6))} -> 10000 | C6: =AVERAGE(INDIRECT(CONCATENATE("csv!G",$E6)):INDIRECT(CONCATENATE("csv!G",($E6)+4))) -> 26119.06 | D6: =_xlfn.STDEV.S(INDIRECT(CONCATENATE("csv!G",$E6)):INDIRECT(CONCATENATE("csv!G",($E6)+4))) -> 157.83605 | E6: =E5+25 -> 122
A7: {=INDIRECT(CONCATENATE("csv!A",$E7))} -> CA | B7: {=INDIRECT(CONCATENATE("csv!D",$E7))} -> 100000 | C7: =AVERAGE(INDIRECT(CONCATENATE("csv!G",$E7)):INDIRECT(CONCATENATE("csv!G",($E7)+4))) -> 11354.42 | D7: =_xlfn.STDEV.S(INDIRECT(CONCATENATE("csv!G",$E7)):INDIRECT(CONCATENATE("csv!G",($E7)+4))) -> 701.08956 | E7: =E6+25 -> 147
A8: {=INDIRECT(CONCATENATE("csv!A",$E8))} -> PVA | B8: {=INDIRECT(CONCATENATE("csv!D",$E8))} -> 1 | C8: =AVERAGE(INDIRECT(CONCATENATE("csv!G",$E8)):INDIRECT(CONCATENATE("csv!G",($E8)+4))) -> 257999.4 | D8: =_xlfn.STDEV.S(INDIRECT(CONCATENATE("csv!G",$E8)):INDIRECT(CONCATENATE("csv!G",($E8)+4))) -> 3586.3927 | E8: =E7+25 -> 172
A9: {=INDIRECT(CONCATENATE("csv!A",$E9))} -> PVA | B9: {=INDIRECT(CONCATENATE("csv!D",$E9))} -> 10 | C9: =AVERAGE(INDIRECT(CONCATENATE("csv!G",$E9)):INDIRECT(CONCATENATE("csv!G",($E9)+4))) -> 161745.2 | D9: =_xlfn.STDEV.S(INDIRECT(CONCATENATE("csv!G",$E9)):INDIRECT(CONCATENATE("csv!G",($E9)+4))) -> 16114.285 | E9: =E8+25 -> 197
A10: {=INDIRECT(CONCATENATE("csv!A",$E10))} -> PVA | B10: {=INDIRECT(CONCATENATE("csv!D",$E10))} -> 100 | C10: =AVERAGE(INDIRECT(CONCATENATE("csv!G",$E10)):INDIRECT(CONCATENATE("csv!G",($E10)+4))) -> 160598 | D10: =_xlfn.STDEV.S(INDIRECT(CONCATENATE("csv!G",$E10)):INDIRECT(CONCATENATE("csv!G",($E10)+4))) -> 6515.5634 | E10: =E9+25 -> 222
A11: {=INDIRECT(CONCATENATE("csv!A",$E11))} -> PVA | B11: {=INDIRECT(CONCATENATE("csv!D",$E11))} -> 1000 | C11: =AVERAGE(INDIRECT(CONCATENATE("csv!G",$E11)):INDIRECT(CONCATENATE("csv!G",($E11)+4))) -> 67008.36 | D11: =_xlfn.STDEV.S(INDIRECT(CONCATENATE("csv!G",$E11)):INDIRECT(CONCATENATE("csv!G",($E11)+4))) -> 2629.2143 | E11: =E10+25 -> 247
A12: {=INDIRECT(CONCATENATE("csv!A",$E12))} -> PVA | B12: {=INDIRECT(CONCATENATE("csv!D",$E12))} -> 10000 | C12: =AVERAGE(INDIRECT(CONCATENATE("csv!G",$E12)):INDIRECT(CONCATENATE("csv!G",($E12)+4))) -> 54524.1 | D12: =_xlfn.STDEV.S(INDIRECT(CONCATENATE("csv!G",$E12)):INDIRECT(CONCATENATE("csv!G",($E12)+4))) -> 4028.4376 | E12: =E11+25 -> 272
A13: {=INDIRECT(CONCATENATE("csv!A",$E13))} -> PVA | B13: {=INDIRECT(CONCATENATE("csv!D",$E13))} -> 100000 | C13: =AVERAGE(INDIRECT(CONCATENATE("csv!G",$E13)):INDIRECT(CONCATENATE("csv!G",($E13)+4))) -> 13769.44 | D13: =_xlfn.STDEV.S(INDIRECT(CONCATENATE("csv!G",$E13)):INDIRECT(CONCATENATE("csv!G",($E13)+4))) -> 321.5871 | E13: =E12+25 -> 297
A14: {=INDIRECT(CONCATENATE("csv!A",$E14))} -> SPVA | B14: {=INDIRECT(CONCATENATE("csv!D",$E14))} -> 1 | C14: =AVERAGE(INDIRECT(CONCATENATE("csv!G",$E14)):INDIRECT(CONCATENATE("csv!G",($E14)+4))) -> 70914.88 | D14: =_xlfn.STDEV.S(INDIRECT(CONCATENATE("csv!G",$E14)):INDIRECT(CONCATENATE("csv!G",($E14)+4))) -> 1079.2627 | E14: =E13+25 -> 322
... A25: {=INDIRECT(CONCATENATE("csv!A",$E25))} -> SPVA_CERTMON | B25: {=INDIRECT(CONCATENATE("csv!D",$E25))} -> 100000 | C25: =AVERAGE(INDIRECT(CONCATENATE("csv!G",$E25)):INDIRECT(CONCATENATE("csv!G",($E25)+4))) -> 3792.05 | D25: =_xlfn.STDEV.S(INDIRECT(CONCATENATE("csv!G",$E25)):INDIRECT(CONCATENATE("csv!G",($E25)+4))) -> 18.066322 | E25: =E24+25 -> 597

Sheet all
A1: Protocol | B1: Subscribers | C1: Payload Size | D1: Per Sub Uodates | G1: Protocol | H1: Subscribers | I1: Payload Size | J1: Per Sub Uodates | M1: Protocol | N1: Subscribers | O1: Payload Size | P1: Per Sub Uodates | S1: Protocol | T1: Subscribers | U1: Payload Size | V1: Per Sub Uodates
A2: {=INDIRECT(CONCATENATE("csv!A",$E2))} -> CA | B2: {=INDIRECT(CONCATENATE("csv!C",$E2))} -> 1 | C2: {=INDIRECT(CONCATENATE("csv!D",$E2))} -> 1 | D2: =AVERAGE(INDIRECT(CONCATENATE("csv!H",$E2)):INDIRECT(CONCATENATE("csv!H",($E2)+4))) -> 37368.62 | E2: =2 -> 2 | G2: {=INDIRECT(CONCATENATE("csv!A",$K2))} -> PVA | H2: {=INDIRECT(CONCATENATE("csv!C",$K2))} -> 1 | I2: {=INDIRECT(CONCATENATE("csv!D",$K2))} -> 1 | J2: =AVERAGE(INDIRECT(CONCATENATE("csv!H",$K2)):INDIRECT(CONCATENATE("csv!H",($K2)+4))) -> 107248.4 | K2: =E2+150 -> 152 | M2: {=INDIRECT(CONCATENATE("csv!A",$Q2))} -> SPVA | N2: {=INDIRECT(CONCATENATE("csv!C",$Q2))} -> 1 | O2: {=INDIRECT(CONCATENATE("csv!D",$Q2))} -> 1 | P2: =AVERAGE(INDIRECT(CONCATENATE("csv!H",$Q2)):INDIRECT(CONCATENATE("csv!H",($Q2)+4))) -> 75098.86 | Q2: =K2+150 -> 302 | S2: {=INDIRECT(CONCATENATE("csv!A",$W2))} -> SPVA_CERTMON | T2: {=INDIRECT(CONCATENATE("csv!C",$W2))} -> 1 | U2: {=INDIRECT(CONCATENATE("csv!D",$W2))} -> 1 | V2: {=INDIRECT(CONCATENATE("csv!H",$W2))} -> 73641.9 | W2: =Q2+150 -> 452
A3: {=INDIRECT(CONCATENATE("csv!A",$E3))} -> CA | B3: {=INDIRECT(CONCATENATE("csv!C",$E3))} -> 10 | C3: {=INDIRECT(CONCATENATE("csv!D",$E3))} -> 1 | D3: =AVERAGE(INDIRECT(CONCATENATE("csv!H",$E3)):INDIRECT(CONCATENATE("csv!H",($E3)+4))) -> 10985.222 | E3: =E2+5 -> 7 | G3: {=INDIRECT(CONCATENATE("csv!A",$K3))} -> PVA | H3: {=INDIRECT(CONCATENATE("csv!C",$K3))} -> 10 | I3: {=INDIRECT(CONCATENATE("csv!D",$K3))} -> 1 | J3: =AVERAGE(INDIRECT(CONCATENATE("csv!H",$K3)):INDIRECT(CONCATENATE("csv!H",($K3)+4))) -> 7924.374 | K3: =K2+5 -> 157 | M3: {=INDIRECT(CONCATENATE("csv!A",$Q3))} -> SPVA | N3: {=INDIRECT(CONCATENATE("csv!C",$Q3))} -> 10 | O3: {=INDIRECT(CONCATENATE("csv!D",$Q3))} -> 1 | P3: =AVERAGE(INDIRECT(CONCATENATE("csv!H",$Q3)):INDIRECT(CONCATENATE("csv!H",($Q3)+4))) -> 4439.22 | Q3: =Q2+5 -> 307 | S3: {=INDIRECT(CONCATENATE("csv!A",$W3))} -> SPVA_CERTMON | T3: {=INDIRECT(CONCATENATE("csv!C",$W3))} -> 10 | U3: {=INDIRECT(CONCATENATE("csv!D",$W3))} -> 1 | V3: {=INDIRECT(CONCATENATE("csv!H",$W3))} -> 4435.47 | W3: =W2+5 -> 457
A4: {=INDIRECT(CONCATENATE("csv!A",$E4))} -> CA | B4: {=INDIRECT(CONCATENATE("csv!C",$E4))} -> 100 | C4: {=INDIRECT(CONCATENATE("csv!D",$E4))} -> 1 | D4: =AVERAGE(INDIRECT(CONCATENATE("csv!H",$E4)):INDIRECT(CONCATENATE("csv!H",($E4)+4))) -> 217.6896 | E4: =E3+5 -> 12 | G4: {=INDIRECT(CONCATENATE("csv!A",$K4))} -> PVA | H4: {=INDIRECT(CONCATENATE("csv!C",$K4))} -> 100 | I4: {=INDIRECT(CONCATENATE("csv!D",$K4))} -> 1 | J4: =AVERAGE(INDIRECT(CONCATENATE("csv!H",$K4)):INDIRECT(CONCATENATE("csv!H",($K4)+4))) -> 264.7828 | K4: =K3+5 -> 162 | M4: {=INDIRECT(CONCATENATE("csv!A",$Q4))} -> SPVA | N4: {=INDIRECT(CONCATENATE("csv!C",$Q4))} -> 100 | O4: {=INDIRECT(CONCATENATE("csv!D",$Q4))} -> 1 | P4: =AVERAGE(INDIRECT(CONCATENATE("csv!H",$Q4)):INDIRECT(CONCATENATE("csv!H",($Q4)+4))) -> 220.4462 | Q4: =Q3+5 -> 312 | S4: {=INDIRECT(CONCATENATE("csv!A",$W4))} -> SPVA_CERTMON | T4: {=INDIRECT(CONCATENATE("csv!C",$W4))} -> 100 | U4: {=INDIRECT(CONCATENATE("csv!D",$W4))} -> 1 | V4: {=INDIRECT(CONCATENATE("csv!H",$W4))} -> 205.849 | W4: =W3+5 -> 462
A5: {=INDIRECT(CONCATENATE("csv!A",$E5))} -> CA | B5: {=INDIRECT(CONCATENATE("csv!C",$E5))} -> 500 | C5: {=INDIRECT(CONCATENATE("csv!D",$E5))} -> 1 | D5: =AVERAGE(INDIRECT(CONCATENATE("csv!H",$E5)):INDIRECT(CONCATENATE("csv!H",($E5)+4))) -> 130.5768 | E5: =E4+5 -> 17 | G5: {=INDIRECT(CONCATENATE("csv!A",$K5))} -> PVA | H5: {=INDIRECT(CONCATENATE("csv!C",$K5))} -> 500 | I5: {=INDIRECT(CONCATENATE("csv!D",$K5))} -> 1 | J5: =AVERAGE(INDIRECT(CONCATENATE("csv!H",$K5)):INDIRECT(CONCATENATE("csv!H",($K5)+4))) -> 252.1184 | K5: =K4+5 -> 167 | M5: {=INDIRECT(CONCATENATE("csv!A",$Q5))} -> SPVA | N5: {=INDIRECT(CONCATENATE("csv!C",$Q5))} -> 500 | O5: {=INDIRECT(CONCATENATE("csv!D",$Q5))} -> 1 | P5: =AVERAGE(INDIRECT(CONCATENATE("csv!H",$Q5)):INDIRECT(CONCATENATE("csv!H",($Q5)+4))) -> 94.11016 | Q5: =Q4+5 -> 317 | S5: {=INDIRECT(CONCATENATE("csv!A",$W5))} -> SPVA_CERTMON | T5: {=INDIRECT(CONCATENATE("csv!C",$W5))} -> 500 | U5: {=INDIRECT(CONCATENATE("csv!D",$W5))} -> 1 | V5: {=INDIRECT(CONCATENATE("csv!H",$W5))} -> 95.1639 | W5: =W4+5 -> 467
A6: {=INDIRECT(CONCATENATE("csv!A",$E6))} -> CA | B6: {=INDIRECT(CONCATENATE("csv!C",$E6))} -> 1000 | C6: {=INDIRECT(CONCATENATE("csv!D",$E6))} -> 1 | D6: =AVERAGE(INDIRECT(CONCATENATE("csv!H",$E6)):INDIRECT(CONCATENATE("csv!H",($E6)+4))) -> 58.07108 | E6: =E5+5 -> 22 | G6: {=INDIRECT(CONCATENATE("csv!A",$K6))} -> PVA | H6: {=INDIRECT(CONCATENATE("csv!C",$K6))} -> 1000 | I6: {=INDIRECT(CONCATENATE("csv!D",$K6))} -> 1 | J6: =AVERAGE(INDIRECT(CONCATENATE("csv!H",$K6)):INDIRECT(CONCATENATE("csv!H",($K6)+4))) -> 257.9994 | K6: =K5+5 -> 172 | M6: {=INDIRECT(CONCATENATE("csv!A",$Q6))} -> SPVA | N6: {=INDIRECT(CONCATENATE("csv!C",$Q6))} -> 1000 | O6: {=INDIRECT(CONCATENATE("csv!D",$Q6))} -> 1 | P6: =AVERAGE(INDIRECT(CONCATENATE("csv!H",$Q6)):INDIRECT(CONCATENATE("csv!H",($Q6)+4))) -> 70.91488 | Q6: =Q5+5 -> 322 | S6: {=INDIRECT(CONCATENATE("csv!A",$W6))} -> SPVA_CERTMON | T6: {=INDIRECT(CONCATENATE("csv!C",$W6))} -> 1000 | U6: {=INDIRECT(CONCATENATE("csv!D",$W6))} -> 1 | V6: {=INDIRECT(CONCATENATE("csv!H",$W6))} -> 71.5342 | W6: =W5+5 -> 472
A7: {=INDIRECT(CONCATENATE("csv!A",$E7))} -> CA | B7: {=INDIRECT(CONCATENATE("csv!C",$E7))} -> 1 | C7: {=INDIRECT(CONCATENATE("csv!D",$E7))} -> 10 | D7: =AVERAGE(INDIRECT(CONCATENATE("csv!H",$E7)):INDIRECT(CONCATENATE("csv!H",($E7)+4))) -> 33625.18 | E7: =E6+5 -> 27 | G7: {=INDIRECT(CONCATENATE("csv!A",$K7))} -> PVA | H7: {=INDIRECT(CONCATENATE("csv!C",$K7))} -> 1 | I7: {=INDIRECT(CONCATENATE("csv!D",$K7))} -> 10 | J7: =AVERAGE(INDIRECT(CONCATENATE("csv!H",$K7)):INDIRECT(CONCATENATE("csv!H",($K7)+4))) -> 107652.8 | K7: =K6+5 -> 177 | M7: {=INDIRECT(CONCATENATE("csv!A",$Q7))} -> SPVA | N7: {=INDIRECT(CONCATENATE("csv!C",$Q7))} -> 1 | O7: {=INDIRECT(CONCATENATE("csv!D",$Q7))} -> 10 | P7: =AVERAGE(INDIRECT(CONCATENATE("csv!H",$Q7)):INDIRECT(CONCATENATE("csv!H",($Q7)+4))) -> 75308.74 | Q7: =Q6+5 -> 327 | S7: {=INDIRECT(CONCATENATE("csv!A",$W7))} -> SPVA_CERTMON | T7: {=INDIRECT(CONCATENATE("csv!C",$W7))} -> 1 | U7: {=INDIRECT(CONCATENATE("csv!D",$W7))} -> 10 | V7: {=INDIRECT(CONCATENATE("csv!H",$W7))} -> 72590.7 | W7: =W6+5 -> 477
A8: {=INDIRECT(CONCATENATE("csv!A",$E8))} -> CA | B8: {=INDIRECT(CONCATENATE("csv!C",$E8))} -> 10 | C8: {=INDIRECT(CONCATENATE("csv!D",$E8))} -> 10 | D8: =AVERAGE(INDIRECT(CONCATENATE("csv!H",$E8)):INDIRECT(CONCATENATE("csv!H",($E8)+4))) -> 13046.5 | E8: =E7+5 -> 32 | G8: {=INDIRECT(CONCATENATE("csv!A",$K8))} -> PVA | H8: {=INDIRECT(CONCATENATE("csv!C",$K8))} -> 10 | I8: {=INDIRECT(CONCATENATE("csv!D",$K8))} -> 10 | J8: =AVERAGE(INDIRECT(CONCATENATE("csv!H",$K8)):INDIRECT(CONCATENATE("csv!H",($K8)+4))) -> 11154.68 | K8: =K7+5 -> 182 | M8: {=INDIRECT(CONCATENATE("csv!A",$Q8))} -> SPVA | N8: {=INDIRECT(CONCATENATE("csv!C",$Q8))} -> 10 | O8: {=INDIRECT(CONCATENATE("csv!D",$Q8))} -> 10 | P8: =AVERAGE(INDIRECT(CONCATENATE("csv!H",$Q8)):INDIRECT(CONCATENATE("csv!H",($Q8)+4))) -> 3955.276 | Q8: =Q7+5 -> 332 | S8: {=INDIRECT(CONCATENATE("csv!A",$W8))} -> SPVA_CERTMON | T8: {=INDIRECT(CONCATENATE("csv!C",$W8))} -> 10 | U8: {=INDIRECT(CONCATENATE("csv!D",$W8))} -> 10 | V8: {=INDIRECT(CONCATENATE("csv!H",$W8))} -> 3976.34 | W8: =W7+5 -> 482
A9: {=INDIRECT(CONCATENATE("csv!A",$E9))} -> CA | B9: {=INDIRECT(CONCATENATE("csv!C",$E9))} -> 100 | C9: {=INDIRECT(CONCATENATE("csv!D",$E9))} -> 10 | D9: =AVERAGE(INDIRECT(CONCATENATE("csv!H",$E9)):INDIRECT(CONCATENATE("csv!H",($E9)+4))) -> 190.8918 | E9: =E8+5 -> 37 | G9: {=INDIRECT(CONCATENATE("csv!A",$K9))} -> PVA | H9: {=INDIRECT(CONCATENATE("csv!C",$K9))} -> 100 | I9: {=INDIRECT(CONCATENATE("csv!D",$K9))} -> 10 | J9: =AVERAGE(INDIRECT(CONCATENATE("csv!H",$K9)):INDIRECT(CONCATENATE("csv!H",($K9)+4))) -> 314.4616 | K9: =K8+5 -> 187 | M9: {=INDIRECT(CONCATENATE("csv!A",$Q9))} -> SPVA | N9: {=INDIRECT(CONCATENATE("csv!C",$Q9))} -> 100 | O9: {=INDIRECT(CONCATENATE("csv!D",$Q9))} -> 10 | P9: =AVERAGE(INDIRECT(CONCATENATE("csv!H",$Q9)):INDIRECT(CONCATENATE("csv!H",($Q9)+4))) -> 238.1066 | Q9: =Q8+5 -> 337 | S9: {=INDIRECT(CONCATENATE("csv!A",$W9))} -> SPVA_CERTMON | T9: {=INDIRECT(CONCATENATE("csv!C",$W9))} -> 100 | U9: {=INDIRECT(CONCATENATE("csv!D",$W9))} -> 10 | V9: {=INDIRECT(CONCATENATE("csv!H",$W9))} -> 251.135 | W9: =W8+5 -> 487
A10: {=INDIRECT(CONCATENATE("csv!A",$E10))} -> CA | B10: {=INDIRECT(CONCATENATE("csv!C",$E10))} -> 500 | C10: {=INDIRECT(CONCATENATE("csv!D",$E10))} -> 10 | D10: =AVERAGE(INDIRECT(CONCATENATE("csv!H",$E10)):INDIRECT(CONCATENATE("csv!H",($E10)+4))) -> 129.9928 | E10: =E9+5 -> 42 | G10: {=INDIRECT(CONCATENATE("csv!A",$K10))} -> PVA | H10: {=INDIRECT(CONCATENATE("csv!C",$K10))} -> 500 | I10: {=INDIRECT(CONCATENATE("csv!D",$K10))} -> 10 | J10: =AVERAGE(INDIRECT(CONCATENATE("csv!H",$K10)):INDIRECT(CONCATENATE("csv!H",($K10)+4))) -> 138.4386 | K10: =K9+5 -> 192 | M10: {=INDIRECT(CONCATENATE("csv!A",$Q10))} -> SPVA | N10: {=INDIRECT(CONCATENATE("csv!C",$Q10))} -> 500 | O10: {=INDIRECT(CONCATENATE("csv!D",$Q10))} -> 10 | P10: =AVERAGE(INDIRECT(CONCATENATE("csv!H",$Q10)):INDIRECT(CONCATENATE("csv!H",($Q10)+4))) -> 78.01698 | Q10: =Q9+5 -> 342 | S10: {=INDIRECT(CONCATENATE("csv!A",$W10))} -> SPVA_CERTMON | T10: {=INDIRECT(CONCATENATE("csv!C",$W10))} -> 500 | U10: {=INDIRECT(CONCATENATE("csv!D",$W10))} -> 10 | V10: {=INDIRECT(CONCATENATE("csv!H",$W10))} -> 74.0192 | W10: =W9+5 -> 492
A11: {=INDIRECT(CONCATENATE("csv!A",$E11))} -> CA | B11: {=INDIRECT(CONCATENATE("csv!C",$E11))} -> 1000 | C11: {=INDIRECT(CONCATENATE("csv!D",$E11))} -> 10 | D11: =AVERAGE(INDIRECT(CONCATENATE("csv!H",$E11)):INDIRECT(CONCATENATE("csv!H",($E11)+4))) -> 57.8673 | E11: =E10+5 -> 47 | G11: {=INDIRECT(CONCATENATE("csv!A",$K11))} -> PVA | H11: {=INDIRECT(CONCATENATE("csv!C",$K11))} -> 1000 | I11: {=INDIRECT(CONCATENATE("csv!D",$K11))} -> 10 | J11: =AVERAGE(INDIRECT(CONCATENATE("csv!H",$K11)):INDIRECT(CONCATENATE("csv!H",($K11)+4))) -> 161.7452 | K11: =K10+5 -> 197 | M11: {=INDIRECT(CONCATENATE("csv!A",$Q11))} -> SPVA | N11: {=INDIRECT(CONCATENATE("csv!C",$Q11))} -> 1000 | O11: {=INDIRECT(CONCATENATE("csv!D",$Q11))} -> 10 | P11: =AVERAGE(INDIRECT(CONCATENATE("csv!H",$Q11)):INDIRECT(CONCATENATE("csv!H",($Q11)+4))) -> 43.41358 | Q11: =Q10+5 -> 347 | S11: {=INDIRECT(CONCATENATE("csv!A",$W11))} -> SPVA_CERTMON | T11: {=INDIRECT(CONCATENATE("csv!C",$W11))} -> 1000 | U11: {=INDIRECT(CONCATENATE("csv!D",$W11))} -> 10 | V11: {=INDIRECT(CONCATENATE("csv!H",$W11))} -> 43.1343 | W11: =W10+5 -> 497
A12: {=INDIRECT(CONCATENATE("csv!A",$E12))} -> CA | B12: {=INDIRECT(CONCATENATE("csv!C",$E12))} -> 1 | C12: {=INDIRECT(CONCATENATE("csv!D",$E12))} -> 100 | D12: =AVERAGE(INDIRECT(CONCATENATE("csv!H",$E12)):INDIRECT(CONCATENATE("csv!H",($E12)+4))) -> 32086.1 | E12: =E11+5 -> 52 | G12: {=INDIRECT(CONCATENATE("csv!A",$K12))} -> PVA | H12: {=INDIRECT(CONCATENATE("csv!C",$K12))} -> 1 | I12: {=INDIRECT(CONCATENATE("csv!D",$K12))} -> 100 | J12: =AVERAGE(INDIRECT(CONCATENATE("csv!H",$K12)):INDIRECT(CONCATENATE("csv!H",($K12)+4))) -> 99042.12 | K12: =K11+5 -> 202 | M12: {=INDIRECT(CONCATENATE("csv!A",$Q12))} -> SPVA | N12: {=INDIRECT(CONCATENATE("csv!C",$Q12))} -> 1 | O12: {=INDIRECT(CONCATENATE("csv!D",$Q12))} -> 100 | P12: =AVERAGE(INDIRECT(CONCATENATE("csv!H",$Q12)):INDIRECT(CONCATENATE("csv!H",($Q12)+4))) -> 74584.54 | Q12: =Q11+5 -> 352 | S12: {=INDIRECT(CONCATENATE("csv!A",$W12))} -> SPVA_CERTMON | T12: {=INDIRECT(CONCATENATE("csv!C",$W12))} -> 1 | U12: {=INDIRECT(CONCATENATE("csv!D",$W12))} -> 100 | V12: {=INDIRECT(CONCATENATE("csv!H",$W12))} -> 73077.4 | W12: =W11+5 -> 502
A13: {=INDIRECT(CONCATENATE("csv!A",$E13))} -> CA | B13: {=INDIRECT(CONCATENATE("csv!C",$E13))} -> 10 | C13: {=INDIRECT(CONCATENATE("csv!D",$E13))} -> 100 | D13: =AVERAGE(INDIRECT(CONCATENATE("csv!H",$E13)):INDIRECT(CONCATENATE("csv!H",($E13)+4))) -> 10181.898 | E13: =E12+5 -> 57 | G13: {=INDIRECT(CONCATENATE("csv!A",$K13))} -> PVA | H13: {=INDIRECT(CONCATENATE("csv!C",$K13))} -> 10 | I13: {=INDIRECT(CONCATENATE("csv!D",$K13))} -> 100 | J13: =AVERAGE(INDIRECT(CONCATENATE("csv!H",$K13)):INDIRECT(CONCATENATE("csv!H",($K13)+4))) -> 8841.064 | K13: =K12+5 -> 207 | M13: {=INDIRECT(CONCATENATE("csv!A",$Q13))} -> SPVA | N13: {=INDIRECT(CONCATENATE("csv!C",$Q13))} -> 10 | O13: {=INDIRECT(CONCATENATE("csv!D",$Q13))} -> 100 | P13: =AVERAGE(INDIRECT(CONCATENATE("csv!H",$Q13)):INDIRECT(CONCATENATE("csv!H",($Q13)+4))) -> 4588.506 | Q13: =Q12+5 -> 357 | S13: {=INDIRECT(CONCATENATE("csv!A",$W13))} -> SPVA_CERTMON | T13: {=INDIRECT(CONCATENATE("csv!C",$W13))} -> 10 | U13: {=INDIRECT(CONCATENATE("csv!D",$W13))} -> 100 | V13: {=INDIRECT(CONCATENATE("csv!H",$W13))} -> 4731.83 | W13: =W12+5 -> 507
A14: {=INDIRECT(CONCATENATE("csv!A",$E14))} -> CA | B14: {=INDIRECT(CONCATENATE("csv!C",$E14))} -> 100 | C14: {=INDIRECT(CONCATENATE("csv!D",$E14))} -> 100 | D14: =AVERAGE(INDIRECT(CONCATENATE("csv!H",$E14)):INDIRECT(CONCATENATE("csv!H",($E14)+4))) -> 203.8738 | E14: =E13+5 -> 62 | G14: {=INDIRECT(CONCATENATE("csv!A",$K14))} -> PVA | H14: {=INDIRECT(CONCATENATE("csv!C",$K14))} -> 100 | I14: {=INDIRECT(CONCATENATE("csv!D",$K14))} -> 100 | J14: =AVERAGE(INDIRECT(CONCATENATE("csv!H",$K14)):INDIRECT(CONCATENATE("csv!H",($K14)+4))) -> 578.2574 | K14: =K13+5 -> 212 | M14: {=INDIRECT(CONCATENATE("csv!A",$Q14))} -> SPVA | N14: {=INDIRECT(CONCATENATE("csv!C",$Q14))} -> 100 | O14: {=INDIRECT(CONCATENATE("csv!D",$Q14))} -> 100 | P14: =AVERAGE(INDIRECT(CONCATENATE("csv!H",$Q14)):INDIRECT(CONCATENATE("csv!H",($Q14)+4))) -> 365.0218 | Q14: =Q13+5 -> 362 | S14: {=INDIRECT(CONCATENATE("csv!A",$W14))} -> SPVA_CERTMON | T14: {=INDIRECT(CONCATENATE("csv!C",$W14))} -> 100 | U14: {=INDIRECT(CONCATENATE("csv!D",$W14))} -> 100 | V14: {=INDIRECT(CONCATENATE("csv!H",$W14))} -> 371.328 | W14: =W13+5 -> 512
... A31: {=INDIRECT(CONCATENATE("csv!A",$E31))} -> CA | B31: {=INDIRECT(CONCATENATE("csv!C",$E31))} -> 1000 | C31: {=INDIRECT(CONCATENATE("csv!D",$E31))} -> 100000 | D31: =AVERAGE(INDIRECT(CONCATENATE("csv!H",$E31)):INDIRECT(CONCATENATE("csv!H",($E31)+4))) -> 11.35442 | E31: =E30+5 -> 147 | G31: {=INDIRECT(CONCATENATE("csv!A",$K31))} -> PVA | H31: {=INDIRECT(CONCATENATE("csv!C",$K31))} -> 1000 | I31: {=INDIRECT(CONCATENATE("csv!D",$K31))} -> 100000 | J31: =AVERAGE(INDIRECT(CONCATENATE("csv!H",$K31)):INDIRECT(CONCATENATE("csv!H",($K31)+4))) -> 13.76944 | K31: =K30+5 -> 297 | M31: {=INDIRECT(CONCATENATE("csv!A",$Q31))} -> SPVA | N31: {=INDIRECT(CONCATENATE("csv!C",$Q31))} -> 1000 | O31: {=INDIRECT(CONCATENATE("csv!D",$Q31))} -> 100000 | P31: =AVERAGE(INDIRECT(CONCATENATE("csv!H",$Q31)):INDIRECT(CONCATENATE("csv!H",($Q31)+4))) -> 3.732224 | Q31: =Q30+5 -> 447 | S31: {=INDIRECT(CONCATENATE("csv!A",$W31))} -> SPVA_CERTMON | T31: {=INDIRECT(CONCATENATE("csv!C",$W31))} -> 1000 | U31: {=INDIRECT(CONCATENATE("csv!D",$W31))} -> 100000 | V31: {=INDIRECT(CONCATENATE("csv!H",$W31))} -> 3.79699 | W31: =W30+5 -> 597

Sheet Throughput Summary
A1: Protocol | B1: Topology | C1: Payload | D1: Subs | E1: Mean Ups | F1: Stddev | G1: Min | H1: Max | I1: Drops
A2: {=INDIRECT(CONCATENATE("csv!A",$J2))} -> CA | B2: {=INDIRECT(CONCATENATE("csv!E",$J2))} -> loopback | C2: {=INDIRECT(CONCATENATE("csv!D",$J2))} -> 1 | D2: {=INDIRECT(CONCATENATE("csv!C",$J2))} -> 1 | E2: =AVERAGE(INDIRECT(CONCATENATE("csv!H",$J2)):INDIRECT(CONCATENATE("csv!H",($J2)+4))) -> 37368.62 | F2: =STDEV(INDIRECT(CONCATENATE("csv!H",$J2)):INDIRECT(CONCATENATE("csv!H",($J2)+4))) -> 5258.4625 | G2: =MIN(INDIRECT(CONCATENATE("csv!H",$J2)):INDIRECT(CONCATENATE("csv!H",($J2)+4))) -> 31468.6 | H2: =MAX(INDIRECT(CONCATENATE("csv!H",$J2)):INDIRECT(CONCATENATE("csv!H",($J2)+4))) -> 42766.4 | I2: =SUM(INDIRECT(CONCATENATE("csv!J",$J2)):INDIRECT(CONCATENATE("csv!J",($J2)+4))) -> 59642152 | J2: 2
A3: {=INDIRECT(CONCATENATE("csv!A",$J3))} -> CA | B3: {=INDIRECT(CONCATENATE("csv!E",$J3))} -> loopback | C3: {=INDIRECT(CONCATENATE("csv!D",$J3))} -> 1 | D3: {=INDIRECT(CONCATENATE("csv!C",$J3))} -> 10 | E3: =AVERAGE(INDIRECT(CONCATENATE("csv!H",$J3)):INDIRECT(CONCATENATE("csv!H",($J3)+4))) -> 10985.222 | F3: =STDEV(INDIRECT(CONCATENATE("csv!H",$J3)):INDIRECT(CONCATENATE("csv!H",($J3)+4))) -> 1021.4464 | G3: =MIN(INDIRECT(CONCATENATE("csv!H",$J3)):INDIRECT(CONCATENATE("csv!H",($J3)+4))) -> 9249.21 | H3: =MAX(INDIRECT(CONCATENATE("csv!H",$J3)):INDIRECT(CONCATENATE("csv!H",($J3)+4))) -> 11682.8 | I3: =SUM(INDIRECT(CONCATENATE("csv!J",$J3)):INDIRECT(CONCATENATE("csv!J",($J3)+4))) -> 195723374 | J3: =J2+5 -> 7
A4: {=INDIRECT(CONCATENATE("csv!A",$J4))} -> CA | B4: {=INDIRECT(CONCATENATE("csv!E",$J4))} -> loopback | C4: {=INDIRECT(CONCATENATE("csv!D",$J4))} -> 1 | D4: {=INDIRECT(CONCATENATE("csv!C",$J4))} -> 100 | E4: =AVERAGE(INDIRECT(CONCATENATE("csv!H",$J4)):INDIRECT(CONCATENATE("csv!H",($J4)+4))) -> 217.6896 | F4: =STDEV(INDIRECT(CONCATENATE("csv!H",$J4)):INDIRECT(CONCATENATE("csv!H",($J4)+4))) -> 16.553212 | G4: =MIN(INDIRECT(CONCATENATE("csv!H",$J4)):INDIRECT(CONCATENATE("csv!H",($J4)+4))) -> 201.02 | H4: =MAX(INDIRECT(CONCATENATE("csv!H",$J4)):INDIRECT(CONCATENATE("csv!H",($J4)+4))) -> 241.956 | I4: =SUM(INDIRECT(CONCATENATE("csv!J",$J4)):INDIRECT(CONCATENATE("csv!J",($J4)+4))) -> 363346787 | J4: =J3+5 -> 12
A5: {=INDIRECT(CONCATENATE("csv!A",$J5))} -> CA | B5: {=INDIRECT(CONCATENATE("csv!E",$J5))} -> loopback | C5: {=INDIRECT(CONCATENATE("csv!D",$J5))} -> 1 | D5: {=INDIRECT(CONCATENATE("csv!C",$J5))} -> 500 | E5: =AVERAGE(INDIRECT(CONCATENATE("csv!H",$J5)):INDIRECT(CONCATENATE("csv!H",($J5)+4))) -> 130.5768 | F5: =STDEV(INDIRECT(CONCATENATE("csv!H",$J5)):INDIRECT(CONCATENATE("csv!H",($J5)+4))) -> 3.2708093 | G5: =MIN(INDIRECT(CONCATENATE("csv!H",$J5)):INDIRECT(CONCATENATE("csv!H",($J5)+4))) -> 124.865 | H5: =MAX(INDIRECT(CONCATENATE("csv!H",$J5)):INDIRECT(CONCATENATE("csv!H",($J5)+4))) -> 132.911 | I5: =SUM(INDIRECT(CONCATENATE("csv!J",$J5)):INDIRECT(CONCATENATE("csv!J",($J5)+4))) -> 387285837 | J5: =J4+5 -> 17
A6: {=INDIRECT(CONCATENATE("csv!A",$J6))} -> CA | B6: {=INDIRECT(CONCATENATE("csv!E",$J6))} -> loopback | C6: {=INDIRECT(CONCATENATE("csv!D",$J6))} -> 1 | D6: {=INDIRECT(CONCATENATE("csv!C",$J6))} -> 1000 | E6: =AVERAGE(INDIRECT(CONCATENATE("csv!H",$J6)):INDIRECT(CONCATENATE("csv!H",($J6)+4))) -> 58.07108 | F6: =STDEV(INDIRECT(CONCATENATE("csv!H",$J6)):INDIRECT(CONCATENATE("csv!H",($J6)+4))) -> 2.3063854 | G6: =MIN(INDIRECT(CONCATENATE("csv!H",$J6)):INDIRECT(CONCATENATE("csv!H",($J6)+4))) -> 55.5002 | H6: =MAX(INDIRECT(CONCATENATE("csv!H",$J6)):INDIRECT(CONCATENATE("csv!H",($J6)+4))) -> 61.2502 | I6: =SUM(INDIRECT(CONCATENATE("csv!J",$J6)):INDIRECT(CONCATENATE("csv!J",($J6)+4))) -> 395176598 | J6: =J5+5 -> 22
A7: {=INDIRECT(CONCATENATE("csv!A",$J7))} -> CA | B7: {=INDIRECT(CONCATENATE("csv!E",$J7))} -> loopback | C7: {=INDIRECT(CONCATENATE("csv!D",$J7))} -> 10 | D7: {=INDIRECT(CONCATENATE("csv!C",$J7))} -> 1 | E7: =AVERAGE(INDIRECT(CONCATENATE("csv!H",$J7)):INDIRECT(CONCATENATE("csv!H",($J7)+4))) -> 33625.18 | F7: =STDEV(INDIRECT(CONCATENATE("csv!H",$J7)):INDIRECT(CONCATENATE("csv!H",($J7)+4))) -> 3400.8573 | G7: =MIN(INDIRECT(CONCATENATE("csv!H",$J7)):INDIRECT(CONCATENATE("csv!H",($J7)+4))) -> 30018 | H7: =MAX(INDIRECT(CONCATENATE("csv!H",$J7)):INDIRECT(CONCATENATE("csv!H",($J7)+4))) -> 37459.4 | I7: =SUM(INDIRECT(CONCATENATE("csv!J",$J7)):INDIRECT(CONCATENATE("csv!J",($J7)+4))) -> 58600019 | J7: =J6+5 -> 27
A8: {=INDIRECT(CONCATENATE("csv!A",$J8))} -> CA | B8: {=INDIRECT(CONCATENATE("csv!E",$J8))} -> loopback | C8: {=INDIRECT(CONCATENATE("csv!D",$J8))} -> 10 | D8: {=INDIRECT(CONCATENATE("csv!C",$J8))} -> 10 | E8: =AVERAGE(INDIRECT(CONCATENATE("csv!H",$J8)):INDIRECT(CONCATENATE("csv!H",($J8)+4))) -> 13046.5 | F8: =STDEV(INDIRECT(CONCATENATE("csv!H",$J8)):INDIRECT(CONCATENATE("csv!H",($J8)+4))) -> 1741.4917 | G8: =MIN(INDIRECT(CONCATENATE("csv!H",$J8)):INDIRECT(CONCATENATE("csv!H",($J8)+4))) -> 11330.6 | H8: =MAX(INDIRECT(CONCATENATE("csv!H",$J8)):INDIRECT(CONCATENATE("csv!H",($J8)+4))) -> 14963.3 | I8: =SUM(INDIRECT(CONCATENATE("csv!J",$J8)):INDIRECT(CONCATENATE("csv!J",($J8)+4))) -> 191863248 | J8: =J7+5 -> 32
A9: {=INDIRECT(CONCATENATE("csv!A",$J9))} -> CA | B9: {=INDIRECT(CONCATENATE("csv!E",$J9))} -> loopback | C9: {=INDIRECT(CONCATENATE("csv!D",$J9))} -> 10 | D9: {=INDIRECT(CONCATENATE("csv!C",$J9))} -> 100 | E9: =AVERAGE(INDIRECT(CONCATENATE("csv!H",$J9)):INDIRECT(CONCATENATE("csv!H",($J9)+4))) -> 190.8918 | F9: =STDEV(INDIRECT(CONCATENATE("csv!H",$J9)):INDIRECT(CONCATENATE("csv!H",($J9)+4))) -> 5.7931871 | G9: =MIN(INDIRECT(CONCATENATE("csv!H",$J9)):INDIRECT(CONCATENATE("csv!H",($J9)+4))) -> 183.688 | H9: =MAX(INDIRECT(CONCATENATE("csv!H",$J9)):INDIRECT(CONCATENATE("csv!H",($J9)+4))) -> 196.727 | I9: =SUM(INDIRECT(CONCATENATE("csv!J",$J9)):INDIRECT(CONCATENATE("csv!J",($J9)+4))) -> 365634400 | J9: =J8+5 -> 37
A10: {=INDIRECT(CONCATENATE("csv!A",$J10))} -> CA | B10: {=INDIRECT(CONCATENATE("csv!E",$J10))} -> loopback | C10: {=INDIRECT(CONCATENATE("csv!D",$J10))} -> 10 | D10: {=INDIRECT(CONCATENATE("csv!C",$J10))} -> 500 | E10: =AVERAGE(INDIRECT(CONCATENATE("csv!H",$J10)):INDIRECT(CONCATENATE("csv!H",($J10)+4))) -> 129.9928 | F10: =STDEV(INDIRECT(CONCATENATE("csv!H",$J10)):INDIRECT(CONCATENATE("csv!H",($J10)+4))) -> 2.1080611 | G10: =MIN(INDIRECT(CONCATENATE("csv!H",$J10)):INDIRECT(CONCATENATE("csv!H",($J10)+4))) -> 126.462 | H10: =MAX(INDIRECT(CONCATENATE("csv!H",$J10)):INDIRECT(CONCATENATE("csv!H",($J10)+4))) -> 131.921 | I10: =SUM(INDIRECT(CONCATENATE("csv!J",$J10)):INDIRECT(CONCATENATE("csv!J",($J10)+4))) -> 388402090 | J10: =J9+5 -> 42
A11: {=INDIRECT(CONCATENATE("csv!A",$J11))} -> CA | B11: {=INDIRECT(CONCATENATE("csv!E",$J11))} -> loopback | C11: {=INDIRECT(CONCATENATE("csv!D",$J11))} -> 10 | D11: {=INDIRECT(CONCATENATE("csv!C",$J11))} -> 1000 | E11: =AVERAGE(INDIRECT(CONCATENATE("csv!H",$J11)):INDIRECT(CONCATENATE("csv!H",($J11)+4))) -> 57.8673 | F11: =STDEV(INDIRECT(CONCATENATE("csv!H",$J11)):INDIRECT(CONCATENATE("csv!H",($J11)+4))) -> 2.3995449 | G11: =MIN(INDIRECT(CONCATENATE("csv!H",$J11)):INDIRECT(CONCATENATE("csv!H",($J11)+4))) -> 54.5143 | H11: =MAX(INDIRECT(CONCATENATE("csv!H",$J11)):INDIRECT(CONCATENATE("csv!H",($J11)+4))) -> 60.248 | I11: =SUM(INDIRECT(CONCATENATE("csv!J",$J11)):INDIRECT(CONCATENATE("csv!J",($J11)+4))) -> 393860713 | J11: =J10+5 -> 47
A12: {=INDIRECT(CONCATENATE("csv!A",$J12))} -> CA | B12: {=INDIRECT(CONCATENATE("csv!E",$J12))} -> loopback | C12: {=INDIRECT(CONCATENATE("csv!D",$J12))} -> 100 | D12: {=INDIRECT(CONCATENATE("csv!C",$J12))} -> 1 | E12: =AVERAGE(INDIRECT(CONCATENATE("csv!H",$J12)):INDIRECT(CONCATENATE("csv!H",($J12)+4))) -> 32086.1 | F12: =STDEV(INDIRECT(CONCATENATE("csv!H",$J12)):INDIRECT(CONCATENATE("csv!H",($J12)+4))) -> 3737.5153 | G12: =MIN(INDIRECT(CONCATENATE("csv!H",$J12)):INDIRECT(CONCATENATE("csv!H",($J12)+4))) -> 28523.4 | H12: =MAX(INDIRECT(CONCATENATE("csv!H",$J12)):INDIRECT(CONCATENATE("csv!H",($J12)+4))) -> 37747 | I12: =SUM(INDIRECT(CONCATENATE("csv!J",$J12)):INDIRECT(CONCATENATE("csv!J",($J12)+4))) -> 56721305 | J12: =J11+5 -> 52
A13: {=INDIRECT(CONCATENATE("csv!A",$J13))} -> CA | B13: {=INDIRECT(CONCATENATE("csv!E",$J13))} -> loopback | C13: {=INDIRECT(CONCATENATE("csv!D",$J13))} -> 100 | D13: {=INDIRECT(CONCATENATE("csv!C",$J13))} -> 10 | E13: =AVERAGE(INDIRECT(CONCATENATE("csv!H",$J13)):INDIRECT(CONCATENATE("csv!H",($J13)+4))) -> 10181.898 | F13: =STDEV(INDIRECT(CONCATENATE("csv!H",$J13)):INDIRECT(CONCATENATE("csv!H",($J13)+4))) -> 1571.2257 | G13: =MIN(INDIRECT(CONCATENATE("csv!H",$J13)):INDIRECT(CONCATENATE("csv!H",($J13)+4))) -> 8519.7 | H13: =MAX(INDIRECT(CONCATENATE("csv!H",$J13)):INDIRECT(CONCATENATE("csv!H",($J13)+4))) -> 12137.9 | I13: =SUM(INDIRECT(CONCATENATE("csv!J",$J13)):INDIRECT(CONCATENATE("csv!J",($J13)+4))) -> 194568044 | J13: =J12+5 -> 57
A14: {=INDIRECT(CONCATENATE("csv!A",$J14))} -> CA | B14: {=INDIRECT(CONCATENATE("csv!E",$J14))} -> loopback | C14: {=INDIRECT(CONCATENATE("csv!D",$J14))} -> 100 | D14: {=INDIRECT(CONCATENATE("csv!C",$J14))} -> 100 | E14: =AVERAGE(INDIRECT(CONCATENATE("csv!H",$J14)):INDIRECT(CONCATENATE("csv!H",($J14)+4))) -> 203.8738 | F14: =STDEV(INDIRECT(CONCATENATE("csv!H",$J14)):INDIRECT(CONCATENATE("csv!H",($J14)+4))) -> 12.221136 | G14: =MIN(INDIRECT(CONCATENATE("csv!H",$J14)):INDIRECT(CONCATENATE("csv!H",($J14)+4))) -> 192.179 | H14: =MAX(INDIRECT(CONCATENATE("csv!H",$J14)):INDIRECT(CONCATENATE("csv!H",($J14)+4))) -> 217.886 | I14: =SUM(INDIRECT(CONCATENATE("csv!J",$J14)):INDIRECT(CONCATENATE("csv!J",($J14)+4))) -> 360062070 | J14: =J13+5 -> 62
... A121: {=INDIRECT(CONCATENATE("csv!A",$J121))} -> SPVA_CERTMON | B121: {=INDIRECT(CONCATENATE("csv!E",$J121))} -> loopback | C121: {=INDIRECT(CONCATENATE("csv!D",$J121))} -> 100000 | D121: {=INDIRECT(CONCATENATE("csv!C",$J121))} -> 1000 | E121: =AVERAGE(INDIRECT(CONCATENATE("csv!H",$J121)):INDIRECT(CONCATENATE("csv!H",($J121)+4))) -> 3.79205 | F121: =STDEV(INDIRECT(CONCATENATE("csv!H",$J121)):INDIRECT(CONCATENATE("csv!H",($J121)+4))) -> 0.018066322 | G121: =MIN(INDIRECT(CONCATENATE("csv!H",$J121)):INDIRECT(CONCATENATE("csv!H",($J121)+4))) -> 3.76848 | H121: =MAX(INDIRECT(CONCATENATE("csv!H",$J121)):INDIRECT(CONCATENATE("csv!H",($J121)+4))) -> 3.81842 | I121: =SUM(INDIRECT(CONCATENATE("csv!J",$J121)):INDIRECT(CONCATENATE("csv!J",($J121)+4))) -> 18254482 | J121: =J120+5 -> 597

Sheet csv
A1: protocol | B1: payload_mode | C1: subscribers | D1: payload_bytes | E1: topology | F1: iteration | G1: updates_per_second | H1: per_sub_updates_per_second | I1: total_updates | J1: drops | K1: errors | L1: duration_seconds | M1: pva_queue_size | N1: <== | O1: PASTE CSV to the left
A2: CA | B2: raw | C2: 1 | D2: 1 | E2: loopback | F2: 1 | G2: 32589.9 | H2: 32589.9 | I2: 163088 | J2: 12677315 | K2: 0 | L2: 5.00425 | M2: 0
A3: CA | B3: raw | C3: 1 | D3: 1 | E3: loopback | F3: 2 | G3: 42766.4 | H3: 42766.4 | I3: 214046 | J3: 12063966 | K3: 0 | L3: 5.005 | M3: 0
A4: CA | B4: raw | C4: 1 | D4: 1 | E4: loopback | F4: 3 | G4: 37786.6 | H4: 37786.6 | I4: 189102 | J4: 11578923 | K4: 0 | L4: 5.00448 | M4: 0
A5: CA | B5: raw | C5: 1 | D5: 1 | E5: loopback | F5: 4 | G5: 42231.6 | H5: 42231.6 | I5: 211171 | J5: 11611192 | K5: 0 | L5: 5.0003 | M5: 0
A6: CA | B6: raw | C6: 1 | D6: 1 | E6: loopback | F6: 5 | G6: 31468.6 | H6: 31468.6 | I6: 157626 | J6: 11710756 | K6: 0 | L6: 5.00899 | M6: 0
A7: CA | B7: raw | C7: 10 | D7: 1 | E7: loopback | F7: 1 | G7: 108742 | H7: 10874.2 | I7: 544256 | J7: 39206994 | K7: 0 | L7: 5.00501 | M7: 0
A8: CA | B8: raw | C8: 10 | D8: 1 | E8: loopback | F8: 2 | G8: 92492.1 | H8: 9249.21 | I8: 462470 | J8: 39230940 | K8: 0 | L8: 5.0001 | M8: 0
A9: CA | B9: raw | C9: 10 | D9: 1 | E9: loopback | F9: 3 | G9: 115673 | H9: 11567.3 | I9: 578706 | J9: 39179211 | K9: 0 | L9: 5.00296 | M9: 0
A10: CA | B10: raw | C10: 10 | D10: 1 | E10: loopback | F10: 4 | G10: 116828 | H10: 11682.8 | I10: 584624 | J10: 38744356 | K10: 0 | L10: 5.00414 | M10: 0
A11: CA | B11: raw | C11: 10 | D11: 1 | E11: loopback | F11: 5 | G11: 115526 | H11: 11552.6 | I11: 577707 | J11: 39361873 | K11: 0 | L11: 5.00067 | M11: 0
A12: CA | B12: raw | C12: 100 | D12: 1 | E12: loopback | F12: 1 | G12: 21556.3 | H12: 215.563 | I12: 107852 | J12: 72328914 | K12: 0 | L12: 5.00328 | M12: 0
A13: CA | B13: raw | C13: 100 | D13: 1 | E13: loopback | F13: 2 | G13: 22519.7 | H13: 225.197 | I13: 112712 | J13: 72340588 | K13: 0 | L13: 5.00503 | M13: 0
... A601: SPVA_CERTMON | B601: raw | C601: 1000 | D601: 100000 | E601: loopback | F601: 5 | G601: 3788.56 | H601: 3.78856 | I601: 18951 | J601: 3643487 | K601: 0 | L601: 5.00217 | M601: 4

Sheet csv_phase
A1: test_type | B1: protocol | C1: iteration | D1: phase | E1: duration_us | F1: <== | G1: PASTE connection phase CSV to the left | K1: =A1 -> test_type | L1: =B1 -> protocol | M1: =C1 -> iteration | N1: =D1 -> phase | O1: =E1 -> duration_us | U1: Phase | V1: PVA (baseline) | X1: SPVA | Z1: SPVA_CERTMON
A2: connection_phase | B2: PVA | C2: 1 | D2: search | E2: 887 | K2: {=INDIRECT(_xlfn.CONCAT("A",$Q2))} -> connection_phase | L2: {=INDIRECT(_xlfn.CONCAT("B",$Q2))} -> PVA | M2: {=INDIRECT(_xlfn.CONCAT("C",$Q2))} -> 1 | N2: {=INDIRECT(_xlfn.CONCAT("D",$Q2))} -> create_channel | O2: {=INDIRECT(_xlfn.CONCAT("E",$Q2))} -> 307 | Q2: 5 | U2: {=INDIRECT(CONCATENATE("csv_phase!N",2+$AB2))} -> search | V2: =AVERAGE(INDIRECT(CONCATENATE("csv_phase!O",2+($AB2))):INDIRECT(CONCATENATE("csv_phase!O",2+($AB2)+49)))/1000 -> 2.9872 | W2: =_xlfn.STDEV.S(INDIRECT(CONCATENATE("csv_phase!O",2+($AB2))):INDIRECT(CONCATENATE("csv_phase!O",2+($AB2)+49)))/1000 -> 2.5096778 | X2: =AVERAGE(INDIRECT(CONCATENATE("csv_phase!O",2+($AB2)+250)):INDIRECT(CONCATENATE("csv_phase!O",2+($AB2)+49+250)))/1000 -> 1.97126 | Y2: =_xlfn.STDEV.S(INDIRECT(CONCATENATE("csv_phase!O",2+($AB2)+250)):INDIRECT(CONCATENATE("csv_phase!O",2+($AB2)+49+250)))/1000 -> 1.3914742 | Z2: =AVERAGE(INDIRECT(CONCATENATE("csv_phase!O",2+($AB2)+500)):INDIRECT(CONCATENATE("csv_phase!O",2+($AB2)+49+500)))/1000 -> 4.28358 | AA2: =_xlfn.STDEV.S(INDIRECT(CONCATENATE("csv_phase!O",2+($AB2)+500)):INDIRECT(CONCATENATE("csv_phase!O",2+($AB2)+49+500)))/1000 -> 2.7539697 | AB2: 50
A3: connection_phase | B3: PVA | C3: 1 | D3: tcp_connect | E3: 119 | K3: {=INDIRECT(_xlfn.CONCAT("A",$Q3))} -> connection_phase | L3: {=INDIRECT(_xlfn.CONCAT("B",$Q3))} -> PVA | M3: {=INDIRECT(_xlfn.CONCAT("C",$Q3))} -> 2 | N3: {=INDIRECT(_xlfn.CONCAT("D",$Q3))} -> create_channel | O3: {=INDIRECT(_xlfn.CONCAT("E",$Q3))} -> 261 | Q3: 10 | U3: {=INDIRECT(CONCATENATE("csv_phase!N",2+$AB3))} -> tcp_connect | V3: =AVERAGE(INDIRECT(CONCATENATE("csv_phase!O",2+($AB3))):INDIRECT(CONCATENATE("csv_phase!O",2+($AB3)+49)))/1000 -> 0.12036 | W3: =_xlfn.STDEV.S(INDIRECT(CONCATENATE("csv_phase!O",2+($AB3))):INDIRECT(CONCATENATE("csv_phase!O",2+($AB3)+49)))/1000 -> 0.11792851 | X3: =AVERAGE(INDIRECT(CONCATENATE("csv_phase!O",2+($AB3)+250)):INDIRECT(CONCATENATE("csv_phase!O",2+($AB3)+49+250)))/1000 -> 5.22268 | Y3: =_xlfn.STDEV.S(INDIRECT(CONCATENATE("csv_phase!O",2+($AB3)+250)):INDIRECT(CONCATENATE("csv_phase!O",2+($AB3)+49+250)))/1000 -> 3.2408031 | Z3: =AVERAGE(INDIRECT(CONCATENATE("csv_phase!O",2+($AB3)+500)):INDIRECT(CONCATENATE("csv_phase!O",2+($AB3)+49+500)))/1000 -> 13.75054 | AA3: =_xlfn.STDEV.S(INDIRECT(CONCATENATE("csv_phase!O",2+($AB3)+500)):INDIRECT(CONCATENATE("csv_phase!O",2+($AB3)+49+500)))/1000 -> 3.3204096 | AB3: 100
A4: connection_phase | B4: PVA | C4: 1 | D4: validation | E4: 128 | K4: {=INDIRECT(_xlfn.CONCAT("A",$Q4))} -> connection_phase | L4: {=INDIRECT(_xlfn.CONCAT("B",$Q4))} -> PVA | M4: {=INDIRECT(_xlfn.CONCAT("C",$Q4))} -> 3 | N4: {=INDIRECT(_xlfn.CONCAT("D",$Q4))} -> create_channel | O4: {=INDIRECT(_xlfn.CONCAT("E",$Q4))} -> 270 | Q4: 15 | U4: {=INDIRECT(CONCATENATE("csv_phase!N",2+$AB4))} -> validation | V4: =AVERAGE(INDIRECT(CONCATENATE("csv_phase!O",2+($AB4))):INDIRECT(CONCATENATE("csv_phase!O",2+($AB4)+49)))/1000 -> 0.29078 | W4: =_xlfn.STDEV.S(INDIRECT(CONCATENATE("csv_phase!O",2+($AB4))):INDIRECT(CONCATENATE("csv_phase!O",2+($AB4)+49)))/1000 -> 0.19501568 | X4: =AVERAGE(INDIRECT(CONCATENATE("csv_phase!O",2+($AB4)+250)):INDIRECT(CONCATENATE("csv_phase!O",2+($AB4)+49+250)))/1000 -> 0.53796 | Y4: =_xlfn.STDEV.S(INDIRECT(CONCATENATE("csv_phase!O",2+($AB4)+250)):INDIRECT(CONCATENATE("csv_phase!O",2+($AB4)+49+250)))/1000 -> 0.3686258 | Z4: =AVERAGE(INDIRECT(CONCATENATE("csv_phase!O",2+($AB4)+500)):INDIRECT(CONCATENATE("csv_phase!O",2+($AB4)+49+500)))/1000 -> 0.74076 | AA4: =_xlfn.STDEV.S(INDIRECT(CONCATENATE("csv_phase!O",2+($AB4)+500)):INDIRECT(CONCATENATE("csv_phase!O",2+($AB4)+49+500)))/1000 -> 0.28725958 | AB4: 200
A5: connection_phase | B5: PVA | C5: 1 | D5: create_channel | E5: 307 | K5: {=INDIRECT(_xlfn.CONCAT("A",$Q5))} -> connection_phase | L5: {=INDIRECT(_xlfn.CONCAT("B",$Q5))} -> PVA | M5: {=INDIRECT(_xlfn.CONCAT("C",$Q5))} -> 4 | N5: {=INDIRECT(_xlfn.CONCAT("D",$Q5))} -> create_channel | O5: {=INDIRECT(_xlfn.CONCAT("E",$Q5))} -> 260 | Q5: 20 | U5: {=INDIRECT(CONCATENATE("csv_phase!N",2+$AB5))} -> create_channel | V5: =AVERAGE(INDIRECT(CONCATENATE("csv_phase!O",2+($AB5))):INDIRECT(CONCATENATE("csv_phase!O",2+($AB5)+49)))/1000 -> 0.4616 | W5: =_xlfn.STDEV.S(INDIRECT(CONCATENATE("csv_phase!O",2+($AB5))):INDIRECT(CONCATENATE("csv_phase!O",2+($AB5)+49)))/1000 -> 0.37529238 | X5: =AVERAGE(INDIRECT(CONCATENATE("csv_phase!O",2+($AB5)+250)):INDIRECT(CONCATENATE("csv_phase!O",2+($AB5)+49+250)))/1000 -> 0.34066 | Y5: =_xlfn.STDEV.S(INDIRECT(CONCATENATE("csv_phase!O",2+($AB5)+250)):INDIRECT(CONCATENATE("csv_phase!O",2+($AB5)+49+250)))/1000 -> 0.064353808 | Z5: =AVERAGE(INDIRECT(CONCATENATE("csv_phase!O",2+($AB5)+500)):INDIRECT(CONCATENATE("csv_phase!O",2+($AB5)+49+500)))/1000 -> 15.26008 | AA5: =_xlfn.STDEV.S(INDIRECT(CONCATENATE("csv_phase!O",2+($AB5)+500)):INDIRECT(CONCATENATE("csv_phase!O",2+($AB5)+49+500)))/1000 -> 2.4466084 | AB5: 0
A6: connection_phase | B6: PVA | C6: 1 | D6: total | E6: 1441 | K6: {=INDIRECT(_xlfn.CONCAT("A",$Q6))} -> connection_phase | L6: {=INDIRECT(_xlfn.CONCAT("B",$Q6))} -> PVA | M6: {=INDIRECT(_xlfn.CONCAT("C",$Q6))} -> 5 | N6: {=INDIRECT(_xlfn.CONCAT("D",$Q6))} -> create_channel | O6: {=INDIRECT(_xlfn.CONCAT("E",$Q6))} -> 247 | Q6: 25 | U6: TOTAL | V6: =SUM(V2:V5) -> 3.85994 | X6: =SUM(X2:X5) -> 8.07256 | Z6: =SUM(Z2:Z5) -> 34.03496
A7: connection_phase | B7: PVA | C7: 2 | D7: search | E7: 857 | K7: {=INDIRECT(_xlfn.CONCAT("A",$Q7))} -> connection_phase | L7: {=INDIRECT(_xlfn.CONCAT("B",$Q7))} -> PVA | M7: {=INDIRECT(_xlfn.CONCAT("C",$Q7))} -> 6 | N7: {=INDIRECT(_xlfn.CONCAT("D",$Q7))} -> create_channel | O7: {=INDIRECT(_xlfn.CONCAT("E",$Q7))} -> 175 | Q7: 30
A8: connection_phase | B8: PVA | C8: 2 | D8: tcp_connect | E8: 101 | K8: {=INDIRECT(_xlfn.CONCAT("A",$Q8))} -> connection_phase | L8: {=INDIRECT(_xlfn.CONCAT("B",$Q8))} -> PVA | M8: {=INDIRECT(_xlfn.CONCAT("C",$Q8))} -> 7 | N8: {=INDIRECT(_xlfn.CONCAT("D",$Q8))} -> create_channel | O8: {=INDIRECT(_xlfn.CONCAT("E",$Q8))} -> 304 | Q8: 35
A9: connection_phase | B9: PVA | C9: 2 | D9: validation | E9: 119 | K9: {=INDIRECT(_xlfn.CONCAT("A",$Q9))} -> connection_phase | L9: {=INDIRECT(_xlfn.CONCAT("B",$Q9))} -> PVA | M9: {=INDIRECT(_xlfn.CONCAT("C",$Q9))} -> 8 | N9: {=INDIRECT(_xlfn.CONCAT("D",$Q9))} -> create_channel | O9: {=INDIRECT(_xlfn.CONCAT("E",$Q9))} -> 249 | Q9: 40
A10: connection_phase | B10: PVA | C10: 2 | D10: create_channel | E10: 261 | K10: {=INDIRECT(_xlfn.CONCAT("A",$Q10))} -> connection_phase | L10: {=INDIRECT(_xlfn.CONCAT("B",$Q10))} -> PVA | M10: {=INDIRECT(_xlfn.CONCAT("C",$Q10))} -> 9 | N10: {=INDIRECT(_xlfn.CONCAT("D",$Q10))} -> create_channel | O10: {=INDIRECT(_xlfn.CONCAT("E",$Q10))} -> 669 | Q10: 45
A11: connection_phase | B11: PVA | C11: 2 | D11: total | E11: 1338 | K11: {=INDIRECT(_xlfn.CONCAT("A",$Q11))} -> connection_phase | L11: {=INDIRECT(_xlfn.CONCAT("B",$Q11))} -> PVA | M11: {=INDIRECT(_xlfn.CONCAT("C",$Q11))} -> 10 | N11: {=INDIRECT(_xlfn.CONCAT("D",$Q11))} -> create_channel | O11: {=INDIRECT(_xlfn.CONCAT("E",$Q11))} -> 301 | Q11: 50
A12: connection_phase | B12: PVA | C12: 3 | D12: search | E12: 848 | K12: {=INDIRECT(_xlfn.CONCAT("A",$Q12))} -> connection_phase | L12: {=INDIRECT(_xlfn.CONCAT("B",$Q12))} -> PVA | M12: {=INDIRECT(_xlfn.CONCAT("C",$Q12))} -> 11 | N12: {=INDIRECT(_xlfn.CONCAT("D",$Q12))} -> create_channel | O12: {=INDIRECT(_xlfn.CONCAT("E",$Q12))} -> 261 | Q12: 55
A13: connection_phase | B13: PVA | C13: 3 | D13: tcp_connect | E13: 130 | K13: {=INDIRECT(_xlfn.CONCAT("A",$Q13))} -> connection_phase | L13: {=INDIRECT(_xlfn.CONCAT("B",$Q13))} -> PVA | M13: {=INDIRECT(_xlfn.CONCAT("C",$Q13))} -> 12 | N13: {=INDIRECT(_xlfn.CONCAT("D",$Q13))} -> create_channel | O13: {=INDIRECT(_xlfn.CONCAT("E",$Q13))} -> 548 | Q13: 60
A14: connection_phase | B14: PVA | C14: 3 | D14: validation | E14: 106 | K14: {=INDIRECT(_xlfn.CONCAT("A",$Q14))} -> connection_phase | L14: {=INDIRECT(_xlfn.CONCAT("B",$Q14))} -> PVA | M14: {=INDIRECT(_xlfn.CONCAT("C",$Q14))} -> 13 | N14: {=INDIRECT(_xlfn.CONCAT("D",$Q14))} -> create_channel | O14: {=INDIRECT(_xlfn.CONCAT("E",$Q14))} -> 282 | Q14: 65
A15: connection_phase | B15: PVA | C15: 3 | D15: create_channel | E15: 270 | K15: {=INDIRECT(_xlfn.CONCAT("A",$Q15))} -> connection_phase | L15: {=INDIRECT(_xlfn.CONCAT("B",$Q15))} -> PVA | M15: {=INDIRECT(_xlfn.CONCAT("C",$Q15))} -> 14 | N15: {=INDIRECT(_xlfn.CONCAT("D",$Q15))} -> create_channel | O15: {=INDIRECT(_xlfn.CONCAT("E",$Q15))} -> 420 | Q15: 70
A16: connection_phase | B16: PVA | C16: 3 | D16: total | E16: 1354 | K16: {=INDIRECT(_xlfn.CONCAT("A",$Q16))} -> connection_phase | L16: {=INDIRECT(_xlfn.CONCAT("B",$Q16))} -> PVA | M16: {=INDIRECT(_xlfn.CONCAT("C",$Q16))} -> 15 | N16: {=INDIRECT(_xlfn.CONCAT("D",$Q16))} -> create_channel | O16: {=INDIRECT(_xlfn.CONCAT("E",$Q16))} -> 831 | Q16: 75
A17: connection_phase | B17: PVA | C17: 4 | D17: search | E17: 988 | K17: {=INDIRECT(_xlfn.CONCAT("A",$Q17))} -> connection_phase | L17: {=INDIRECT(_xlfn.CONCAT("B",$Q17))} -> PVA | M17: {=INDIRECT(_xlfn.CONCAT("C",$Q17))} -> 16 | N17: {=INDIRECT(_xlfn.CONCAT("D",$Q17))} -> create_channel | O17: {=INDIRECT(_xlfn.CONCAT("E",$Q17))} -> 909 | Q17: 80
A18: connection_phase | B18: PVA | C18: 4 | D18: tcp_connect | E18: 168 | K18: {=INDIRECT(_xlfn.CONCAT("A",$Q18))} -> connection_phase | L18: {=INDIRECT(_xlfn.CONCAT("B",$Q18))} -> PVA | M18: {=INDIRECT(_xlfn.CONCAT("C",$Q18))} -> 17 | N18: {=INDIRECT(_xlfn.CONCAT("D",$Q18))} -> create_channel | O18: {=INDIRECT(_xlfn.CONCAT("E",$Q18))} -> 369 | Q18: 85
... A751: connection_phase | B751: SPVA_CERTMON | C751: 50 | D751: total | E751: 31177 | K751: {=INDIRECT(_xlfn.CONCAT("A",$Q751))} -> connection_phase | L751: {=INDIRECT(_xlfn.CONCAT("B",$Q751))} -> SPVA_CERTMON | M751: {=INDIRECT(_xlfn.CONCAT("C",$Q751))} -> 50 | N751: {=INDIRECT(_xlfn.CONCAT("D",$Q751))} -> validation | O751: {=INDIRECT(_xlfn.CONCAT("E",$Q751))} -> 861 | Q751: 749
